<?xml version='1.0' encoding='utf-8'?>
<mujoco model="simple_quad_v0">
  <compiler angle="radian" coordinate="local" autolimits="false" />
  <option timestep="0.002" integrator="RK4" gravity="0 0 -9.81" />
  <size njmax="100" nconmax="100" />
  <asset>
    <material name="floor" rgba="0.28 0.30 0.31 1" />
  </asset>
  <worldbody>
    <light name="key" pos="0 -1.5 2.5" dir="0 1 -1" />
    <geom name="floor" type="plane" size="2 2 0.02" material="floor" friction="0.9 0.02 0.001" />
    <camera name="track" mode="trackcom" pos="0.65 -0.9 0.45" xyaxes="0.82 0.57 0 -0.20 0.29 0.94" />
    <body name="target_marker" mocap="true" pos="0.45 0 0.025">
      <geom name="target_marker_geom" type="sphere" size="0.035" rgba="1 0.12 0.08 0.75" contype="0" conaffinity="0" />
    </body>
    <body name="body" pos="0 0 0.17">
      <freejoint name="root_free" />
      <inertial pos="0 7.48275e-18 1.26887e-17" euler="0 -0 0" mass="0.410343" diaginertia="0.00259371 0.000372065 0.00290555" />
      <geom type="box" pos="0 0 0" euler="0 -0 0" size="0.0500000007 0.139978006 0.0149999997" rgba="0.615686 0.811765 0.929412 1" name="body_visual" contype="0" conaffinity="0" group="2" mass="0" />
      <geom type="box" pos="0 0 0" euler="0 -0 0" size="0.0500000007 0.139978006 0.0149999997" rgba="0.35 0.35 0.35 0.18" name="body_collision" group="3" friction="0.9 0.02 0.001" mass="0" />
      <body name="leg_5" pos="-0.05 0.125 2.77556e-17" euler="1.5708 -0 0">
        <joint name="revolute_back_left_hip" type="hinge" axis="1 0 0" range="-0.9 0.9" limited="true" damping="0.8" armature="0.002" frictionloss="0.01" />
        <inertial pos="-0.005 -0.0304821 0.0218425" euler="-2.19256 -0 0" mass="0.0544248" diaginertia="3.93186e-05 1.4351e-05 2.58747e-05" />
        <geom type="box" pos="-0.0050000003 -0.0304815537 0.0218421691" euler="-2.19256 -0 0" size="0.00499999896 0.0100000016 0.0474853325" rgba="0.647059 0.647059 0.647059 1" name="leg_5_visual" contype="0" conaffinity="0" group="2" mass="0" />
        <geom type="box" pos="-0.0050000003 -0.0304815537 0.0218421691" euler="-2.19256 -0 0" size="0.00499999896 0.0100000016 0.0474853325" rgba="0.35 0.35 0.35 0.18" name="leg_5_collision" group="3" friction="0.9 0.02 0.001" mass="0" />
        <body name="leg_6" pos="-0.01 -0.0609641 0.043685" euler="-0.735344 0 0">
          <joint name="revolute_back_left_knee" type="hinge" axis="1 -0 -0" range="-1.25 1.25" limited="true" damping="0.8" armature="0.002" frictionloss="0.01" />
          <inertial pos="-0.005 0 -0.0375" euler="0 -0 0" mass="0.0544248" diaginertia="3.93186e-05 3.80365e-05 2.18916e-06" />
          <geom type="box" pos="-0.0050000003 -3.7252903e-09 -0.0374999982" euler="0 -0 0" size="0.00499999896 0.0100000016 0.0474853325" rgba="0.647059 0.647059 0.647059 1" name="leg_6_visual" contype="0" conaffinity="0" group="2" mass="0" />
          <geom type="box" pos="-0.0050000003 -3.7252903e-09 -0.0374999982" euler="0 -0 0" size="0.00499999896 0.0100000016 0.0474853325" rgba="0.35 0.35 0.35 0.18" name="leg_6_collision" group="3" friction="0.9 0.02 0.001" mass="0" />
        </body>
      </body>
      <body name="leg_1" pos="0.05 0.125 2.77556e-17" euler="1.5708 -0 0">
        <joint name="revolute_back_right_hip" type="hinge" axis="-1 0 0" range="-0.9 0.9" limited="true" damping="0.8" armature="0.002" frictionloss="0.01" />
        <inertial pos="0.005 -0.0315225 0.0203121" euler="-2.1432 -0 0" mass="0.0544248" diaginertia="3.93186e-05 1.27065e-05 2.75192e-05" />
        <geom type="box" pos="0.0049999997 -0.0315228829 0.0203122132" euler="-2.1432 -0 0" size="0.00499999896 0.0100000016 0.0474853325" rgba="0.647059 0.647059 0.647059 1" name="leg_1_visual" contype="0" conaffinity="0" group="2" mass="0" />
        <geom type="box" pos="0.0049999997 -0.0315228829 0.0203122132" euler="-2.1432 -0 0" size="0.00499999896 0.0100000016 0.0474853325" rgba="0.35 0.35 0.35 0.18" name="leg_1_collision" group="3" friction="0.9 0.02 0.001" mass="0" />
        <body name="leg_3" pos="0.01 -0.063045 0.0406243" euler="-2.1432 -0 0">
          <joint name="revolute_back_right_knee" type="hinge" axis="-1 0 0" range="-1.25 1.25" limited="true" damping="0.8" armature="0.002" frictionloss="0.01" />
          <inertial pos="0.005 0.0374943 -0.000652877" euler="1.55339 -0 0" mass="0.0544248" diaginertia="3.93186e-05 2.20002e-06 3.80256e-05" />
          <geom type="box" pos="0.0049999997 0.0374948964 -0.000652772203" euler="1.55339 -0 0" size="0.00499999896 0.0100000016 0.0474853325" rgba="0.647059 0.647059 0.647059 1" name="leg_3_visual" contype="0" conaffinity="0" group="2" mass="0" />
          <geom type="box" pos="0.0049999997 0.0374948964 -0.000652772203" euler="1.55339 -0 0" size="0.00499999896 0.0100000016 0.0474853325" rgba="0.35 0.35 0.35 0.18" name="leg_3_collision" group="3" friction="0.9 0.02 0.001" mass="0" />
        </body>
      </body>
      <body name="leg_2" pos="-0.05 -0.125 1.38778e-17" euler="1.5708 -0 0">
        <joint name="revolute_front_left_hip" type="hinge" axis="1 0 0" range="-0.9 0.9" limited="true" damping="0.8" armature="0.002" frictionloss="0.01" />
        <inertial pos="-0.005 -0.0248154 -0.0281149" euler="-0.723141 0 0" mass="0.0544248" diaginertia="3.93186e-05 2.23388e-05 1.78869e-05" />
        <geom type="box" pos="-0.0050000003 -0.0248154201 -0.0281149502" euler="-0.723141 0 0" size="0.00499999896 0.0100000016 0.0474853325" rgba="0.647059 0.647059 0.647059 1" name="leg_2_visual" contype="0" conaffinity="0" group="2" mass="0" />
        <geom type="box" pos="-0.0050000003 -0.0248154201 -0.0281149502" euler="-0.723141 0 0" size="0.00499999896 0.0100000016 0.0474853325" rgba="0.35 0.35 0.35 0.18" name="leg_2_collision" group="3" friction="0.9 0.02 0.001" mass="0" />
        <body name="leg_4" pos="-0.01 -0.0496307 -0.0562298" euler="-0.723141 0 0">
          <joint name="revolute_front_left_knee" type="hinge" axis="1 0 0" range="-1.25 1.25" limited="true" damping="0.8" armature="0.002" frictionloss="0.01" />
          <inertial pos="-0.005 -0.0374406 0.00210991" euler="-1.62709 0 0" mass="0.0544248" diaginertia="3.93186e-05 2.30264e-06 3.7923e-05" />
          <geom type="box" pos="-0.0050000003 -0.0374406422 0.00210989278" euler="-1.62709 0 0" size="0.00499999896 0.0100000016 0.0474853325" rgba="0.647059 0.647059 0.647059 1" name="leg_4_visual" contype="0" conaffinity="0" group="2" mass="0" />
          <geom type="box" pos="-0.0050000003 -0.0374406422 0.00210989278" euler="-1.62709 0 0" size="0.00499999896 0.0100000016 0.0474853325" rgba="0.35 0.35 0.35 0.18" name="leg_4_collision" group="3" friction="0.9 0.02 0.001" mass="0" />
        </body>
      </body>
      <body name="leg" pos="0.05 -0.125 -1.38778e-17" euler="6.66134e-16 -0 0">
        <joint name="revolute_front_right_hip" type="hinge" axis="-1 0 0" range="-0.9 0.9" limited="true" damping="0.8" armature="0.002" frictionloss="0.01" />
        <inertial pos="0.005 0.0265888 -0.026444" euler="0.788128 -0 0" mass="0.0544248" diaginertia="3.93186e-05 2.0015e-05 2.02107e-05" />
        <geom type="box" pos="0.0049999997 0.0265887544 -0.026444025" euler="0.788128 -0 0" size="0.00499999896 0.0100000016 0.0474853325" rgba="0.647059 0.647059 0.647059 1" name="leg_visual" contype="0" conaffinity="0" group="2" mass="0" />
        <geom type="box" pos="0.0049999997 0.0265887544 -0.026444025" euler="0.788128 -0 0" size="0.00499999896 0.0100000016 0.0474853325" rgba="0.35 0.35 0.35 0.18" name="leg_collision" group="3" friction="0.9 0.02 0.001" mass="0" />
        <body name="leg_7" pos="0.01 0.0531776 -0.052888" euler="0.788128 -0 0">
          <joint name="revolute_front_right_knee" type="hinge" axis="-1 0 0" range="-1.25 1.25" limited="true" damping="0.8" armature="0.002" frictionloss="0.01" />
          <inertial pos="0.005 -0.0373662 0.00316528" euler="-1.6553 0 0" mass="0.0544248" diaginertia="3.93186e-05 2.44456e-06 3.77811e-05" />
          <geom type="box" pos="0.0049999997 -0.0373666941 0.00316508231" euler="-1.6553 0 0" size="0.00499999896 0.0100000016 0.0474853325" rgba="0.647059 0.647059 0.647059 1" name="leg_7_visual" contype="0" conaffinity="0" group="2" mass="0" />
          <geom type="box" pos="0.0049999997 -0.0373666941 0.00316508231" euler="-1.6553 0 0" size="0.00499999896 0.0100000016 0.0474853325" rgba="0.35 0.35 0.35 0.18" name="leg_7_collision" group="3" friction="0.9 0.02 0.001" mass="0" />
        </body>
      </body>
    </body>
  </worldbody>
  <actuator>
    <position name="revolute_back_left_hip_servo" joint="revolute_back_left_hip" kp="22" ctrllimited="true" ctrlrange="-0.9 0.9" forcelimited="true" forcerange="-1.37 1.37" />
    <position name="revolute_back_left_knee_servo" joint="revolute_back_left_knee" kp="22" ctrllimited="true" ctrlrange="-1.25 1.25" forcelimited="true" forcerange="-1.37 1.37" />
    <position name="revolute_back_right_hip_servo" joint="revolute_back_right_hip" kp="22" ctrllimited="true" ctrlrange="-0.9 0.9" forcelimited="true" forcerange="-1.37 1.37" />
    <position name="revolute_back_right_knee_servo" joint="revolute_back_right_knee" kp="22" ctrllimited="true" ctrlrange="-1.25 1.25" forcelimited="true" forcerange="-1.37 1.37" />
    <position name="revolute_front_left_hip_servo" joint="revolute_front_left_hip" kp="22" ctrllimited="true" ctrlrange="-0.9 0.9" forcelimited="true" forcerange="-1.37 1.37" />
    <position name="revolute_front_left_knee_servo" joint="revolute_front_left_knee" kp="22" ctrllimited="true" ctrlrange="-1.25 1.25" forcelimited="true" forcerange="-1.37 1.37" />
    <position name="revolute_front_right_hip_servo" joint="revolute_front_right_hip" kp="22" ctrllimited="true" ctrlrange="-0.9 0.9" forcelimited="true" forcerange="-1.37 1.37" />
    <position name="revolute_front_right_knee_servo" joint="revolute_front_right_knee" kp="22" ctrllimited="true" ctrlrange="-1.25 1.25" forcelimited="true" forcerange="-1.37 1.37" />
  </actuator>
</mujoco>