<!--URDF generated by ONSHAPE BY PTC INC, 1.217-->
<robot name="assembly_1">
    <link name="body">
        <inertial>
            <mass value="0.410343" />
            <origin xyz="0 7.48275e-18 1.26887e-17" rpy="0 -0 0" />
            <inertia ixx="0.00259371" ixy="0" ixz="0" iyy="0.000372065" iyz="0" izz="0.00290555" />
        </inertial>
        <visual>
            <origin xyz="0 0 0" rpy="0 -0 0" />
            <geometry>
                <mesh filename="package://assembly_1/meshes/Body.gltf" scale="1 1 1" />
            </geometry>
            <material name="0.615686_0.811765_0.929412_0.000000_0.000000">
                <color rgba="0.615686 0.811765 0.929412 1" />
            </material>
        </visual>
    </link>
    <link name="leg">
        <inertial>
            <mass value="0.0544248" />
            <origin xyz="0.005 0.0265888 -0.026444" rpy="0.788128 -0 0" />
            <inertia ixx="3.93186e-05" ixy="0" ixz="0" iyy="2.0015e-05" iyz="1.79234e-05" izz="2.02107e-05" />
        </inertial>
        <visual>
            <origin xyz="-0.05 0.0881467 0.0886293" rpy="0.788128 -0 0" />
            <geometry>
                <mesh filename="package://assembly_1/meshes/Leg.gltf" scale="1 1 1" />
            </geometry>
            <material name="0.647059_0.647059_0.647059_0.000000_0.000000">
                <color rgba="0.647059 0.647059 0.647059 1" />
            </material>
        </visual>
    </link>
    <link name="leg_1">
        <inertial>
            <mass value="0.0544248" />
            <origin xyz="0.005 -0.0315225 0.0203121" rpy="-2.1432 -0 0" />
            <inertia ixx="3.93186e-05" ixy="0" ixz="0" iyy="1.27065e-05" iyz="1.63219e-05" izz="2.75192e-05" />
        </inertial>
        <visual>
            <origin xyz="-0.05 -0.0677071 -0.105075" rpy="-2.1432 -0 0" />
            <geometry>
                <mesh filename="package://assembly_1/meshes/Leg.gltf" scale="1 1 1" />
            </geometry>
            <material name="0.647059_0.647059_0.647059_0.000000_0.000000">
                <color rgba="0.647059 0.647059 0.647059 1" />
            </material>
        </visual>
    </link>
    <link name="leg_2">
        <inertial>
            <mass value="0.0544248" />
            <origin xyz="-0.005 -0.0248154 -0.0281149" rpy="-0.723141 0 0" />
            <inertia ixx="3.93186e-05" ixy="0" ixz="0" iyy="2.23388e-05" iyz="-1.77849e-05" izz="1.78869e-05" />
        </inertial>
        <visual>
            <origin xyz="-0.06 0.0937163 -0.0827179" rpy="-0.723141 0 0" />
            <geometry>
                <mesh filename="package://assembly_1/meshes/Leg.gltf" scale="1 1 1" />
            </geometry>
            <material name="0.647059_0.647059_0.647059_0.000000_0.000000">
                <color rgba="0.647059 0.647059 0.647059 1" />
            </material>
        </visual>
    </link>
    <link name="leg_3">
        <inertial>
            <mass value="0.0544248" />
            <origin xyz="0.005 0.0374943 -0.000652877" rpy="1.55339 -0 0" />
            <inertia ixx="3.93186e-05" ixy="0" ixz="0" iyy="2.20002e-06" iyz="6.2401e-07" izz="3.80256e-05" />
        </inertial>
        <visual>
            <origin xyz="-0.05 0.00217626 0.124981" rpy="1.55339 -0 0" />
            <geometry>
                <mesh filename="package://assembly_1/meshes/Leg.gltf" scale="1 1 1" />
            </geometry>
            <material name="0.647059_0.647059_0.647059_0.000000_0.000000">
                <color rgba="0.647059 0.647059 0.647059 1" />
            </material>
        </visual>
    </link>
    <link name="leg_4">
        <inertial>
            <mass value="0.0544248" />
            <origin xyz="-0.005 -0.0374406 0.00210991" rpy="-1.62709 0 0" />
            <inertia ixx="3.93186e-05" ixy="0" ixz="0" iyy="2.30264e-06" iyz="2.01373e-06" izz="3.7923e-05" />
        </inertial>
        <visual>
            <origin xyz="-0.06 -0.00703304 -0.124802" rpy="-1.62709 0 0" />
            <geometry>
                <mesh filename="package://assembly_1/meshes/Leg.gltf" scale="1 1 1" />
            </geometry>
            <material name="0.647059_0.647059_0.647059_0.000000_0.000000">
                <color rgba="0.647059 0.647059 0.647059 1" />
            </material>
        </visual>
    </link>
    <link name="leg_5">
        <inertial>
            <mass value="0.0544248" />
            <origin xyz="-0.005 -0.0304821 0.0218425" rpy="-2.19256 -0 0" />
            <inertia ixx="3.93186e-05" ixy="0" ixz="0" iyy="1.4351e-05" iyz="1.69723e-05" izz="2.58747e-05" />
        </inertial>
        <visual>
            <origin xyz="-0.06 -0.0728083 -0.101607" rpy="-2.19256 -0 0" />
            <geometry>
                <mesh filename="package://assembly_1/meshes/Leg.gltf" scale="1 1 1" />
            </geometry>
            <material name="0.647059_0.647059_0.647059_0.000000_0.000000">
                <color rgba="0.647059 0.647059 0.647059 1" />
            </material>
        </visual>
    </link>
    <link name="leg_6">
        <inertial>
            <mass value="0.0544248" />
            <origin xyz="-0.005 0 -0.0375" rpy="0 -0 0" />
            <inertia ixx="3.93186e-05" ixy="0" ixz="0" iyy="3.80365e-05" iyz="0" izz="2.18916e-06" />
        </inertial>
        <visual>
            <origin xyz="-0.06 0.125 -6.12323e-19" rpy="0 -0 0" />
            <geometry>
                <mesh filename="package://assembly_1/meshes/Leg.gltf" scale="1 1 1" />
            </geometry>
            <material name="0.647059_0.647059_0.647059_0.000000_0.000000">
                <color rgba="0.647059 0.647059 0.647059 1" />
            </material>
        </visual>
    </link>
    <link name="leg_7">
        <inertial>
            <mass value="0.0544248" />
            <origin xyz="0.005 -0.0373662 0.00316528" rpy="-1.6553 0 0" />
            <inertia ixx="3.93186e-05" ixy="0" ixz="0" iyy="2.44456e-06" iyz="3.01499e-06" izz="3.77811e-05" />
        </inertial>
        <visual>
            <origin xyz="-0.05 -0.0105509 -0.124554" rpy="-1.6553 0 0" />
            <geometry>
                <mesh filename="package://assembly_1/meshes/Leg.gltf" scale="1 1 1" />
            </geometry>
            <material name="0.647059_0.647059_0.647059_0.000000_0.000000">
                <color rgba="0.647059 0.647059 0.647059 1" />
            </material>
        </visual>
    </link>
    <link name="root" />
    <joint name="fixed_node_to_root_joint" type="fixed">
        <origin xyz="0 0 0" rpy="0 -0 0" />
        <axis xyz="0 0 1" />
        <parent link="root" />
        <child link="body" />
    </joint>
    <joint name="revolute_back_left_hip" type="continuous">
        <origin xyz="-0.05 0.125 2.77556e-17" rpy="1.5708 -0 0" />
        <axis xyz="1 0 0" />
        <parent link="body" />
        <child link="leg_5" />
    </joint>
    <joint name="revolute_back_left_knee" type="continuous">
        <origin xyz="-0.01 -0.0609641 0.043685" rpy="-0.735344 0 0" />
        <axis xyz="1 -0 -0" />
        <parent link="leg_5" />
        <child link="leg_6" />
    </joint>
    <joint name="revolute_back_right_hip" type="continuous">
        <origin xyz="0.05 0.125 2.77556e-17" rpy="1.5708 -0 0" />
        <axis xyz="-1 0 0" />
        <parent link="body" />
        <child link="leg_1" />
    </joint>
    <joint name="revolute_back_right_knee" type="continuous">
        <origin xyz="0.01 -0.063045 0.0406243" rpy="-2.1432 -0 0" />
        <axis xyz="-1 0 0" />
        <parent link="leg_1" />
        <child link="leg_3" />
    </joint>
    <joint name="revolute_front_left_hip" type="continuous">
        <origin xyz="-0.05 -0.125 1.38778e-17" rpy="1.5708 -0 0" />
        <axis xyz="1 0 0" />
        <parent link="body" />
        <child link="leg_2" />
    </joint>
    <joint name="revolute_front_left_knee" type="continuous">
        <origin xyz="-0.01 -0.0496307 -0.0562298" rpy="-0.723141 0 0" />
        <axis xyz="1 0 0" />
        <parent link="leg_2" />
        <child link="leg_4" />
    </joint>
    <joint name="revolute_front_right_hip" type="continuous">
        <origin xyz="0.05 -0.125 -1.38778e-17" rpy="6.66134e-16 -0 0" />
        <axis xyz="-1 0 0" />
        <parent link="body" />
        <child link="leg" />
    </joint>
    <joint name="revolute_front_right_knee" type="continuous">
        <origin xyz="0.01 0.0531776 -0.052888" rpy="0.788128 -0 0" />
        <axis xyz="-1 0 0" />
        <parent link="leg" />
        <child link="leg_7" />
    </joint>
</robot>
